[2024-05-15T13:02:38.267+0000] {local_task_job_runner.py:120} INFO - ::group::Pre task execution logs
[2024-05-15T13:02:38.275+0000] {taskinstance.py:2076} INFO - Dependencies all met for dep_context=non-requeueable deps ti=<TaskInstance: data_ingestion_gcs_dag.upload_file_to_gcs_task manual__2024-05-15T12:57:29.235658+00:00 [queued]>
[2024-05-15T13:02:38.279+0000] {taskinstance.py:2076} INFO - Dependencies all met for dep_context=requeueable deps ti=<TaskInstance: data_ingestion_gcs_dag.upload_file_to_gcs_task manual__2024-05-15T12:57:29.235658+00:00 [queued]>
[2024-05-15T13:02:38.279+0000] {taskinstance.py:2306} INFO - Starting attempt 2 of 2
[2024-05-15T13:02:38.286+0000] {taskinstance.py:2330} INFO - Executing <Task(PythonOperator): upload_file_to_gcs_task> on 2024-05-15 12:57:29.235658+00:00
[2024-05-15T13:02:38.289+0000] {warnings.py:110} WARNING - /home/***/.local/lib/python3.12/site-packages/***/task/task_runner/standard_task_runner.py:61: DeprecationWarning: This process (pid=55) is multi-threaded, use of fork() may lead to deadlocks in the child.
  pid = os.fork()

[2024-05-15T13:02:38.290+0000] {standard_task_runner.py:63} INFO - Started process 57 to run task
[2024-05-15T13:02:38.291+0000] {standard_task_runner.py:90} INFO - Running: ['***', 'tasks', 'run', 'data_ingestion_gcs_dag', 'upload_file_to_gcs_task', 'manual__2024-05-15T12:57:29.235658+00:00', '--job-id', '24', '--raw', '--subdir', 'DAGS_FOLDER/data_ingesting_gcs_dag.py', '--cfg-path', '/tmp/tmp5qqehkit']
[2024-05-15T13:02:38.292+0000] {standard_task_runner.py:91} INFO - Job 24: Subtask upload_file_to_gcs_task
[2024-05-15T13:02:38.314+0000] {task_command.py:426} INFO - Running <TaskInstance: data_ingestion_gcs_dag.upload_file_to_gcs_task manual__2024-05-15T12:57:29.235658+00:00 [running]> on host 980cb962d892
[2024-05-15T13:02:38.352+0000] {taskinstance.py:2648} INFO - Exporting env vars: AIRFLOW_CTX_DAG_OWNER='***' AIRFLOW_CTX_DAG_ID='data_ingestion_gcs_dag' AIRFLOW_CTX_TASK_ID='upload_file_to_gcs_task' AIRFLOW_CTX_EXECUTION_DATE='2024-05-15T12:57:29.235658+00:00' AIRFLOW_CTX_TRY_NUMBER='2' AIRFLOW_CTX_DAG_RUN_ID='manual__2024-05-15T12:57:29.235658+00:00'
[2024-05-15T13:02:38.353+0000] {taskinstance.py:430} INFO - ::endgroup::
[2024-05-15T13:02:38.455+0000] {taskinstance.py:441} INFO - ::group::Post task execution logs
[2024-05-15T13:02:38.455+0000] {taskinstance.py:2905} ERROR - Task failed with exception
Traceback (most recent call last):
  File "/home/airflow/.local/lib/python3.12/site-packages/airflow/models/taskinstance.py", line 465, in _execute_task
    result = _execute_callable(context=context, **execute_callable_kwargs)
             ^^^^^^^^^^^^^^^^^^^^^^^^^^^^^^^^^^^^^^^^^^^^^^^^^^^^^^^^^^^^^
  File "/home/airflow/.local/lib/python3.12/site-packages/airflow/models/taskinstance.py", line 432, in _execute_callable
    return execute_callable(context=context, **execute_callable_kwargs)
           ^^^^^^^^^^^^^^^^^^^^^^^^^^^^^^^^^^^^^^^^^^^^^^^^^^^^^^^^^^^^
  File "/home/airflow/.local/lib/python3.12/site-packages/airflow/models/baseoperator.py", line 400, in wrapper
    return func(self, *args, **kwargs)
           ^^^^^^^^^^^^^^^^^^^^^^^^^^^
  File "/home/airflow/.local/lib/python3.12/site-packages/airflow/operators/python.py", line 235, in execute
    return_value = self.execute_callable()
                   ^^^^^^^^^^^^^^^^^^^^^^^
  File "/home/airflow/.local/lib/python3.12/site-packages/airflow/operators/python.py", line 252, in execute_callable
    return self.python_callable(*self.op_args, **self.op_kwargs)
           ^^^^^^^^^^^^^^^^^^^^^^^^^^^^^^^^^^^^^^^^^^^^^^^^^^^^^
  File "/opt/airflow/dags/data_ingesting_gcs_dag.py", line 57, in upload_file_to_gcs
    blob.upload_from_filename(local_fpath)
  File "/home/airflow/.local/lib/python3.12/site-packages/google/cloud/storage/blob.py", line 2959, in upload_from_filename
    self._handle_filename_and_upload(
  File "/home/airflow/.local/lib/python3.12/site-packages/google/cloud/storage/blob.py", line 2827, in _handle_filename_and_upload
    with open(filename, "rb") as file_obj:
         ^^^^^^^^^^^^^^^^^^^^
FileNotFoundError: [Errno 2] No such file or directory: '/opt/airflow/yellow_tripdata_2021-01.parquet'
[2024-05-15T13:02:38.461+0000] {taskinstance.py:1206} INFO - Marking task as FAILED. dag_id=data_ingestion_gcs_dag, task_id=upload_file_to_gcs_task, run_id=manual__2024-05-15T12:57:29.235658+00:00, execution_date=20240515T125729, start_date=20240515T130238, end_date=20240515T130238
[2024-05-15T13:02:38.467+0000] {standard_task_runner.py:110} ERROR - Failed to execute job 24 for task upload_file_to_gcs_task ([Errno 2] No such file or directory: '/opt/airflow/yellow_tripdata_2021-01.parquet'; 57)
[2024-05-15T13:02:38.471+0000] {local_task_job_runner.py:240} INFO - Task exited with return code 1
[2024-05-15T13:02:38.482+0000] {taskinstance.py:3498} INFO - 0 downstream tasks scheduled from follow-on schedule check
[2024-05-15T13:02:38.484+0000] {local_task_job_runner.py:222} INFO - ::endgroup::
