[2024-05-15T13:12:57.434+0000] {local_task_job_runner.py:120} INFO - ::group::Pre task execution logs
[2024-05-15T13:12:57.467+0000] {taskinstance.py:2076} INFO - Dependencies all met for dep_context=non-requeueable deps ti=<TaskInstance: data_ingestion_gcs_dag.create_bigquery_external_table_task manual__2024-05-15T13:06:01.464781+00:00 [queued]>
[2024-05-15T13:12:57.490+0000] {taskinstance.py:2076} INFO - Dependencies all met for dep_context=requeueable deps ti=<TaskInstance: data_ingestion_gcs_dag.create_bigquery_external_table_task manual__2024-05-15T13:06:01.464781+00:00 [queued]>
[2024-05-15T13:12:57.495+0000] {taskinstance.py:2306} INFO - Starting attempt 1 of 2
[2024-05-15T13:12:57.581+0000] {taskinstance.py:2330} INFO - Executing <Task(BigQueryCreateExternalTableOperator): create_bigquery_external_table_task> on 2024-05-15 13:06:01.464781+00:00
[2024-05-15T13:12:57.599+0000] {warnings.py:110} WARNING - /home/***/.local/lib/python3.12/site-packages/***/task/task_runner/standard_task_runner.py:61: DeprecationWarning: This process (pid=168) is multi-threaded, use of fork() may lead to deadlocks in the child.
  pid = os.fork()

[2024-05-15T13:12:57.606+0000] {standard_task_runner.py:63} INFO - Started process 170 to run task
[2024-05-15T13:12:57.609+0000] {standard_task_runner.py:90} INFO - Running: ['***', 'tasks', 'run', 'data_ingestion_gcs_dag', 'create_bigquery_external_table_task', 'manual__2024-05-15T13:06:01.464781+00:00', '--job-id', '35', '--raw', '--subdir', 'DAGS_FOLDER/data_ingesting_gcs_dag.py', '--cfg-path', '/tmp/tmpwdcg2xrm']
[2024-05-15T13:12:57.615+0000] {standard_task_runner.py:91} INFO - Job 35: Subtask create_bigquery_external_table_task
[2024-05-15T13:12:57.718+0000] {task_command.py:426} INFO - Running <TaskInstance: data_ingestion_gcs_dag.create_bigquery_external_table_task manual__2024-05-15T13:06:01.464781+00:00 [running]> on host 6bd10c6a7f4c
[2024-05-15T13:12:57.888+0000] {taskinstance.py:2648} INFO - Exporting env vars: AIRFLOW_CTX_DAG_OWNER='***' AIRFLOW_CTX_DAG_ID='data_ingestion_gcs_dag' AIRFLOW_CTX_TASK_ID='create_bigquery_external_table_task' AIRFLOW_CTX_EXECUTION_DATE='2024-05-15T13:06:01.464781+00:00' AIRFLOW_CTX_TRY_NUMBER='1' AIRFLOW_CTX_DAG_RUN_ID='manual__2024-05-15T13:06:01.464781+00:00'
[2024-05-15T13:12:57.896+0000] {taskinstance.py:430} INFO - ::endgroup::
[2024-05-15T13:12:57.929+0000] {taskinstance.py:441} INFO - ::group::Post task execution logs
[2024-05-15T13:12:57.946+0000] {taskinstance.py:2905} ERROR - Task failed with exception
Traceback (most recent call last):
  File "/home/airflow/.local/lib/python3.12/site-packages/airflow/models/taskinstance.py", line 465, in _execute_task
    result = _execute_callable(context=context, **execute_callable_kwargs)
             ^^^^^^^^^^^^^^^^^^^^^^^^^^^^^^^^^^^^^^^^^^^^^^^^^^^^^^^^^^^^^
  File "/home/airflow/.local/lib/python3.12/site-packages/airflow/models/taskinstance.py", line 432, in _execute_callable
    return execute_callable(context=context, **execute_callable_kwargs)
           ^^^^^^^^^^^^^^^^^^^^^^^^^^^^^^^^^^^^^^^^^^^^^^^^^^^^^^^^^^^^
  File "/home/airflow/.local/lib/python3.12/site-packages/airflow/models/baseoperator.py", line 400, in wrapper
    return func(self, *args, **kwargs)
           ^^^^^^^^^^^^^^^^^^^^^^^^^^^
  File "/home/airflow/.local/lib/python3.12/site-packages/airflow/providers/google/cloud/operators/bigquery.py", line 1784, in execute
    bq_hook = BigQueryHook(
              ^^^^^^^^^^^^^
  File "/home/airflow/.local/lib/python3.12/site-packages/airflow/providers/google/cloud/hooks/bigquery.py", line 159, in __init__
    super().__init__(**kwargs)
  File "/home/airflow/.local/lib/python3.12/site-packages/airflow/providers/google/common/hooks/base_google.py", line 252, in __init__
    self.extras: dict = self.get_connection(self.gcp_conn_id).extra_dejson
                        ^^^^^^^^^^^^^^^^^^^^^^^^^^^^^^^^^^^^^
  File "/home/airflow/.local/lib/python3.12/site-packages/airflow/hooks/base.py", line 83, in get_connection
    conn = Connection.get_connection_from_secrets(conn_id)
           ^^^^^^^^^^^^^^^^^^^^^^^^^^^^^^^^^^^^^^^^^^^^^^^
  File "/home/airflow/.local/lib/python3.12/site-packages/airflow/models/connection.py", line 519, in get_connection_from_secrets
    raise AirflowNotFoundException(f"The conn_id `{conn_id}` isn't defined")
airflow.exceptions.AirflowNotFoundException: The conn_id `google_cloud_default` isn't defined
[2024-05-15T13:12:57.954+0000] {taskinstance.py:1206} INFO - Marking task as UP_FOR_RETRY. dag_id=data_ingestion_gcs_dag, task_id=create_bigquery_external_table_task, run_id=manual__2024-05-15T13:06:01.464781+00:00, execution_date=20240515T130601, start_date=20240515T131257, end_date=20240515T131257
[2024-05-15T13:12:57.975+0000] {standard_task_runner.py:110} ERROR - Failed to execute job 35 for task create_bigquery_external_table_task (The conn_id `google_cloud_default` isn't defined; 170)
[2024-05-15T13:12:58.016+0000] {local_task_job_runner.py:240} INFO - Task exited with return code 1
[2024-05-15T13:12:58.038+0000] {taskinstance.py:3498} INFO - 0 downstream tasks scheduled from follow-on schedule check
[2024-05-15T13:12:58.041+0000] {local_task_job_runner.py:222} INFO - ::endgroup::
