[2024-05-15T12:45:30.048+0000] {local_task_job_runner.py:120} INFO - ::group::Pre task execution logs
[2024-05-15T12:45:30.055+0000] {taskinstance.py:2076} INFO - Dependencies all met for dep_context=non-requeueable deps ti=<TaskInstance: data_ingestion_gcs_dag.upload_file_to_gcs_task manual__2024-05-15T12:45:23.971290+00:00 [queued]>
[2024-05-15T12:45:30.058+0000] {taskinstance.py:2076} INFO - Dependencies all met for dep_context=requeueable deps ti=<TaskInstance: data_ingestion_gcs_dag.upload_file_to_gcs_task manual__2024-05-15T12:45:23.971290+00:00 [queued]>
[2024-05-15T12:45:30.058+0000] {taskinstance.py:2306} INFO - Starting attempt 1 of 2
[2024-05-15T12:45:30.063+0000] {taskinstance.py:2330} INFO - Executing <Task(PythonOperator): upload_file_to_gcs_task> on 2024-05-15 12:45:23.971290+00:00
[2024-05-15T12:45:30.066+0000] {warnings.py:110} WARNING - /home/***/.local/lib/python3.12/site-packages/***/task/task_runner/standard_task_runner.py:61: DeprecationWarning: This process (pid=68) is multi-threaded, use of fork() may lead to deadlocks in the child.
  pid = os.fork()

[2024-05-15T12:45:30.067+0000] {standard_task_runner.py:63} INFO - Started process 70 to run task
[2024-05-15T12:45:30.067+0000] {standard_task_runner.py:90} INFO - Running: ['***', 'tasks', 'run', 'data_ingestion_gcs_dag', 'upload_file_to_gcs_task', 'manual__2024-05-15T12:45:23.971290+00:00', '--job-id', '15', '--raw', '--subdir', 'DAGS_FOLDER/data_ingesting_gcs_dag.py', '--cfg-path', '/tmp/tmpcqelhtay']
[2024-05-15T12:45:30.068+0000] {standard_task_runner.py:91} INFO - Job 15: Subtask upload_file_to_gcs_task
[2024-05-15T12:45:30.088+0000] {task_command.py:426} INFO - Running <TaskInstance: data_ingestion_gcs_dag.upload_file_to_gcs_task manual__2024-05-15T12:45:23.971290+00:00 [running]> on host f84e7de834f2
[2024-05-15T12:45:30.122+0000] {taskinstance.py:2648} INFO - Exporting env vars: AIRFLOW_CTX_DAG_OWNER='***' AIRFLOW_CTX_DAG_ID='data_ingestion_gcs_dag' AIRFLOW_CTX_TASK_ID='upload_file_to_gcs_task' AIRFLOW_CTX_EXECUTION_DATE='2024-05-15T12:45:23.971290+00:00' AIRFLOW_CTX_TRY_NUMBER='1' AIRFLOW_CTX_DAG_RUN_ID='manual__2024-05-15T12:45:23.971290+00:00'
[2024-05-15T12:45:30.123+0000] {taskinstance.py:430} INFO - ::endgroup::
[2024-05-15T12:45:30.129+0000] {taskinstance.py:441} INFO - ::group::Post task execution logs
[2024-05-15T12:45:30.129+0000] {taskinstance.py:2905} ERROR - Task failed with exception
Traceback (most recent call last):
  File "/home/airflow/.local/lib/python3.12/site-packages/airflow/models/taskinstance.py", line 465, in _execute_task
    result = _execute_callable(context=context, **execute_callable_kwargs)
             ^^^^^^^^^^^^^^^^^^^^^^^^^^^^^^^^^^^^^^^^^^^^^^^^^^^^^^^^^^^^^
  File "/home/airflow/.local/lib/python3.12/site-packages/airflow/models/taskinstance.py", line 432, in _execute_callable
    return execute_callable(context=context, **execute_callable_kwargs)
           ^^^^^^^^^^^^^^^^^^^^^^^^^^^^^^^^^^^^^^^^^^^^^^^^^^^^^^^^^^^^
  File "/home/airflow/.local/lib/python3.12/site-packages/airflow/models/baseoperator.py", line 400, in wrapper
    return func(self, *args, **kwargs)
           ^^^^^^^^^^^^^^^^^^^^^^^^^^^
  File "/home/airflow/.local/lib/python3.12/site-packages/airflow/operators/python.py", line 235, in execute
    return_value = self.execute_callable()
                   ^^^^^^^^^^^^^^^^^^^^^^^
  File "/home/airflow/.local/lib/python3.12/site-packages/airflow/operators/python.py", line 252, in execute_callable
    return self.python_callable(*self.op_args, **self.op_kwargs)
           ^^^^^^^^^^^^^^^^^^^^^^^^^^^^^^^^^^^^^^^^^^^^^^^^^^^^^
  File "/opt/airflow/dags/data_ingesting_gcs_dag.py", line 53, in upload_file_to_gcs
    client = storage.Client()
             ^^^^^^^^^^^^^^^^
  File "/home/airflow/.local/lib/python3.12/site-packages/google/cloud/storage/client.py", line 226, in __init__
    super(Client, self).__init__(
  File "/home/airflow/.local/lib/python3.12/site-packages/google/cloud/client/__init__.py", line 320, in __init__
    _ClientProjectMixin.__init__(self, project=project, credentials=credentials)
  File "/home/airflow/.local/lib/python3.12/site-packages/google/cloud/client/__init__.py", line 268, in __init__
    project = self._determine_default(project)
              ^^^^^^^^^^^^^^^^^^^^^^^^^^^^^^^^
  File "/home/airflow/.local/lib/python3.12/site-packages/google/cloud/client/__init__.py", line 287, in _determine_default
    return _determine_default_project(project)
           ^^^^^^^^^^^^^^^^^^^^^^^^^^^^^^^^^^^
  File "/home/airflow/.local/lib/python3.12/site-packages/google/cloud/_helpers/__init__.py", line 152, in _determine_default_project
    _, project = google.auth.default()
                 ^^^^^^^^^^^^^^^^^^^^^
  File "/home/airflow/.local/lib/python3.12/site-packages/google/auth/_default.py", line 657, in default
    credentials, project_id = checker()
                              ^^^^^^^^^
  File "/home/airflow/.local/lib/python3.12/site-packages/google/auth/_default.py", line 650, in <lambda>
    lambda: _get_explicit_environ_credentials(quota_project_id=quota_project_id),
            ^^^^^^^^^^^^^^^^^^^^^^^^^^^^^^^^^^^^^^^^^^^^^^^^^^^^^^^^^^^^^^^^^^^^
  File "/home/airflow/.local/lib/python3.12/site-packages/google/auth/_default.py", line 270, in _get_explicit_environ_credentials
    credentials, project_id = load_credentials_from_file(
                              ^^^^^^^^^^^^^^^^^^^^^^^^^^^
  File "/home/airflow/.local/lib/python3.12/site-packages/google/auth/_default.py", line 114, in load_credentials_from_file
    raise exceptions.DefaultCredentialsError(
google.auth.exceptions.DefaultCredentialsError: File /.google/credentials/google_credentials.json was not found.
[2024-05-15T12:45:30.134+0000] {taskinstance.py:1206} INFO - Marking task as UP_FOR_RETRY. dag_id=data_ingestion_gcs_dag, task_id=upload_file_to_gcs_task, run_id=manual__2024-05-15T12:45:23.971290+00:00, execution_date=20240515T124523, start_date=20240515T124530, end_date=20240515T124530
[2024-05-15T12:45:30.139+0000] {standard_task_runner.py:110} ERROR - Failed to execute job 15 for task upload_file_to_gcs_task (File /.google/credentials/google_credentials.json was not found.; 70)
[2024-05-15T12:45:30.166+0000] {local_task_job_runner.py:240} INFO - Task exited with return code 1
[2024-05-15T12:45:30.176+0000] {taskinstance.py:3498} INFO - 0 downstream tasks scheduled from follow-on schedule check
[2024-05-15T12:45:30.176+0000] {local_task_job_runner.py:222} INFO - ::endgroup::
