[2024-05-15T13:18:07.093+0000] {local_task_job_runner.py:120} INFO - ::group::Pre task execution logs
[2024-05-15T13:18:07.105+0000] {taskinstance.py:2076} INFO - Dependencies all met for dep_context=non-requeueable deps ti=<TaskInstance: data_ingestion_gcs_dag.create_bigquery_external_table_task manual__2024-05-15T13:14:46.871928+00:00 [queued]>
[2024-05-15T13:18:07.109+0000] {taskinstance.py:2076} INFO - Dependencies all met for dep_context=requeueable deps ti=<TaskInstance: data_ingestion_gcs_dag.create_bigquery_external_table_task manual__2024-05-15T13:14:46.871928+00:00 [queued]>
[2024-05-15T13:18:07.110+0000] {taskinstance.py:2306} INFO - Starting attempt 1 of 2
[2024-05-15T13:18:07.117+0000] {taskinstance.py:2330} INFO - Executing <Task(BigQueryCreateExternalTableOperator): create_bigquery_external_table_task> on 2024-05-15 13:14:46.871928+00:00
[2024-05-15T13:18:07.123+0000] {warnings.py:110} WARNING - /home/***/.local/lib/python3.12/site-packages/***/task/task_runner/standard_task_runner.py:61: DeprecationWarning: This process (pid=123) is multi-threaded, use of fork() may lead to deadlocks in the child.
  pid = os.fork()

[2024-05-15T13:18:07.125+0000] {standard_task_runner.py:63} INFO - Started process 125 to run task
[2024-05-15T13:18:07.125+0000] {standard_task_runner.py:90} INFO - Running: ['***', 'tasks', 'run', 'data_ingestion_gcs_dag', 'create_bigquery_external_table_task', 'manual__2024-05-15T13:14:46.871928+00:00', '--job-id', '42', '--raw', '--subdir', 'DAGS_FOLDER/data_ingesting_gcs_dag.py', '--cfg-path', '/tmp/tmpw2d3e2pw']
[2024-05-15T13:18:07.127+0000] {standard_task_runner.py:91} INFO - Job 42: Subtask create_bigquery_external_table_task
[2024-05-15T13:18:07.160+0000] {task_command.py:426} INFO - Running <TaskInstance: data_ingestion_gcs_dag.create_bigquery_external_table_task manual__2024-05-15T13:14:46.871928+00:00 [running]> on host e0baaada026d
[2024-05-15T13:18:07.212+0000] {taskinstance.py:2648} INFO - Exporting env vars: AIRFLOW_CTX_DAG_OWNER='***' AIRFLOW_CTX_DAG_ID='data_ingestion_gcs_dag' AIRFLOW_CTX_TASK_ID='create_bigquery_external_table_task' AIRFLOW_CTX_EXECUTION_DATE='2024-05-15T13:14:46.871928+00:00' AIRFLOW_CTX_TRY_NUMBER='1' AIRFLOW_CTX_DAG_RUN_ID='manual__2024-05-15T13:14:46.871928+00:00'
[2024-05-15T13:18:07.213+0000] {taskinstance.py:430} INFO - ::endgroup::
[2024-05-15T13:18:07.223+0000] {taskinstance.py:441} INFO - ::group::Post task execution logs
[2024-05-15T13:18:07.227+0000] {taskinstance.py:2905} ERROR - Task failed with exception
Traceback (most recent call last):
  File "/home/airflow/.local/lib/python3.12/site-packages/airflow/models/taskinstance.py", line 465, in _execute_task
    result = _execute_callable(context=context, **execute_callable_kwargs)
             ^^^^^^^^^^^^^^^^^^^^^^^^^^^^^^^^^^^^^^^^^^^^^^^^^^^^^^^^^^^^^
  File "/home/airflow/.local/lib/python3.12/site-packages/airflow/models/taskinstance.py", line 432, in _execute_callable
    return execute_callable(context=context, **execute_callable_kwargs)
           ^^^^^^^^^^^^^^^^^^^^^^^^^^^^^^^^^^^^^^^^^^^^^^^^^^^^^^^^^^^^
  File "/home/airflow/.local/lib/python3.12/site-packages/airflow/models/baseoperator.py", line 400, in wrapper
    return func(self, *args, **kwargs)
           ^^^^^^^^^^^^^^^^^^^^^^^^^^^
  File "/home/airflow/.local/lib/python3.12/site-packages/airflow/providers/google/cloud/operators/bigquery.py", line 1784, in execute
    bq_hook = BigQueryHook(
              ^^^^^^^^^^^^^
  File "/home/airflow/.local/lib/python3.12/site-packages/airflow/providers/google/cloud/hooks/bigquery.py", line 159, in __init__
    super().__init__(**kwargs)
  File "/home/airflow/.local/lib/python3.12/site-packages/airflow/providers/google/common/hooks/base_google.py", line 252, in __init__
    self.extras: dict = self.get_connection(self.gcp_conn_id).extra_dejson
                        ^^^^^^^^^^^^^^^^^^^^^^^^^^^^^^^^^^^^^
  File "/home/airflow/.local/lib/python3.12/site-packages/airflow/hooks/base.py", line 83, in get_connection
    conn = Connection.get_connection_from_secrets(conn_id)
           ^^^^^^^^^^^^^^^^^^^^^^^^^^^^^^^^^^^^^^^^^^^^^^^
  File "/home/airflow/.local/lib/python3.12/site-packages/airflow/models/connection.py", line 519, in get_connection_from_secrets
    raise AirflowNotFoundException(f"The conn_id `{conn_id}` isn't defined")
airflow.exceptions.AirflowNotFoundException: The conn_id `google_cloud_default` isn't defined
[2024-05-15T13:18:07.230+0000] {taskinstance.py:1206} INFO - Marking task as UP_FOR_RETRY. dag_id=data_ingestion_gcs_dag, task_id=create_bigquery_external_table_task, run_id=manual__2024-05-15T13:14:46.871928+00:00, execution_date=20240515T131446, start_date=20240515T131807, end_date=20240515T131807
[2024-05-15T13:18:07.235+0000] {standard_task_runner.py:110} ERROR - Failed to execute job 42 for task create_bigquery_external_table_task (The conn_id `google_cloud_default` isn't defined; 125)
[2024-05-15T13:18:07.265+0000] {local_task_job_runner.py:240} INFO - Task exited with return code 1
[2024-05-15T13:18:07.273+0000] {taskinstance.py:3498} INFO - 0 downstream tasks scheduled from follow-on schedule check
[2024-05-15T13:18:07.274+0000] {local_task_job_runner.py:222} INFO - ::endgroup::
