[2024-05-15T13:07:51.211+0000] {local_task_job_runner.py:120} INFO - ::group::Pre task execution logs
[2024-05-15T13:07:51.219+0000] {taskinstance.py:2076} INFO - Dependencies all met for dep_context=non-requeueable deps ti=<TaskInstance: data_ingestion_gcs_dag.upload_file_to_gcs_task manual__2024-05-15T13:06:01.464781+00:00 [queued]>
[2024-05-15T13:07:51.224+0000] {taskinstance.py:2076} INFO - Dependencies all met for dep_context=requeueable deps ti=<TaskInstance: data_ingestion_gcs_dag.upload_file_to_gcs_task manual__2024-05-15T13:06:01.464781+00:00 [queued]>
[2024-05-15T13:07:51.224+0000] {taskinstance.py:2306} INFO - Starting attempt 1 of 2
[2024-05-15T13:07:51.230+0000] {taskinstance.py:2330} INFO - Executing <Task(PythonOperator): upload_file_to_gcs_task> on 2024-05-15 13:06:01.464781+00:00
[2024-05-15T13:07:51.233+0000] {warnings.py:110} WARNING - /home/***/.local/lib/python3.12/site-packages/***/task/task_runner/standard_task_runner.py:61: DeprecationWarning: This process (pid=100) is multi-threaded, use of fork() may lead to deadlocks in the child.
  pid = os.fork()

[2024-05-15T13:07:51.234+0000] {standard_task_runner.py:63} INFO - Started process 102 to run task
[2024-05-15T13:07:51.234+0000] {standard_task_runner.py:90} INFO - Running: ['***', 'tasks', 'run', 'data_ingestion_gcs_dag', 'upload_file_to_gcs_task', 'manual__2024-05-15T13:06:01.464781+00:00', '--job-id', '33', '--raw', '--subdir', 'DAGS_FOLDER/data_ingesting_gcs_dag.py', '--cfg-path', '/tmp/tmpsds_431u']
[2024-05-15T13:07:51.236+0000] {standard_task_runner.py:91} INFO - Job 33: Subtask upload_file_to_gcs_task
[2024-05-15T13:07:51.258+0000] {task_command.py:426} INFO - Running <TaskInstance: data_ingestion_gcs_dag.upload_file_to_gcs_task manual__2024-05-15T13:06:01.464781+00:00 [running]> on host 6bd10c6a7f4c
[2024-05-15T13:07:51.300+0000] {taskinstance.py:2648} INFO - Exporting env vars: AIRFLOW_CTX_DAG_OWNER='***' AIRFLOW_CTX_DAG_ID='data_ingestion_gcs_dag' AIRFLOW_CTX_TASK_ID='upload_file_to_gcs_task' AIRFLOW_CTX_EXECUTION_DATE='2024-05-15T13:06:01.464781+00:00' AIRFLOW_CTX_TRY_NUMBER='1' AIRFLOW_CTX_DAG_RUN_ID='manual__2024-05-15T13:06:01.464781+00:00'
[2024-05-15T13:07:51.301+0000] {taskinstance.py:430} INFO - ::endgroup::
[2024-05-15T13:07:52.196+0000] {taskinstance.py:441} INFO - ::group::Post task execution logs
[2024-05-15T13:07:52.197+0000] {taskinstance.py:2905} ERROR - Task failed with exception
Traceback (most recent call last):
  File "/home/airflow/.local/lib/python3.12/site-packages/google/cloud/storage/blob.py", line 2637, in _prep_and_do_upload
    created_json = self._do_upload(
                   ^^^^^^^^^^^^^^^^
  File "/home/airflow/.local/lib/python3.12/site-packages/google/cloud/storage/blob.py", line 2443, in _do_upload
    response = self._do_multipart_upload(
               ^^^^^^^^^^^^^^^^^^^^^^^^^^
  File "/home/airflow/.local/lib/python3.12/site-packages/google/cloud/storage/blob.py", line 1956, in _do_multipart_upload
    response = upload.transmit(
               ^^^^^^^^^^^^^^^^
  File "/home/airflow/.local/lib/python3.12/site-packages/google/resumable_media/requests/upload.py", line 153, in transmit
    return _request_helpers.wait_and_retry(
           ^^^^^^^^^^^^^^^^^^^^^^^^^^^^^^^^
  File "/home/airflow/.local/lib/python3.12/site-packages/google/resumable_media/requests/_request_helpers.py", line 155, in wait_and_retry
    response = func()
               ^^^^^^
  File "/home/airflow/.local/lib/python3.12/site-packages/google/resumable_media/requests/upload.py", line 149, in retriable_request
    self._process_response(result)
  File "/home/airflow/.local/lib/python3.12/site-packages/google/resumable_media/_upload.py", line 125, in _process_response
    _helpers.require_status_code(response, (http.client.OK,), self._get_status_code)
  File "/home/airflow/.local/lib/python3.12/site-packages/google/resumable_media/_helpers.py", line 108, in require_status_code
    raise common.InvalidResponse(
google.resumable_media.common.InvalidResponse: ('Request failed with status code', 404, 'Expected one of', 200)

During handling of the above exception, another exception occurred:

Traceback (most recent call last):
  File "/home/airflow/.local/lib/python3.12/site-packages/airflow/models/taskinstance.py", line 465, in _execute_task
    result = _execute_callable(context=context, **execute_callable_kwargs)
             ^^^^^^^^^^^^^^^^^^^^^^^^^^^^^^^^^^^^^^^^^^^^^^^^^^^^^^^^^^^^^
  File "/home/airflow/.local/lib/python3.12/site-packages/airflow/models/taskinstance.py", line 432, in _execute_callable
    return execute_callable(context=context, **execute_callable_kwargs)
           ^^^^^^^^^^^^^^^^^^^^^^^^^^^^^^^^^^^^^^^^^^^^^^^^^^^^^^^^^^^^
  File "/home/airflow/.local/lib/python3.12/site-packages/airflow/models/baseoperator.py", line 400, in wrapper
    return func(self, *args, **kwargs)
           ^^^^^^^^^^^^^^^^^^^^^^^^^^^
  File "/home/airflow/.local/lib/python3.12/site-packages/airflow/operators/python.py", line 235, in execute
    return_value = self.execute_callable()
                   ^^^^^^^^^^^^^^^^^^^^^^^
  File "/home/airflow/.local/lib/python3.12/site-packages/airflow/operators/python.py", line 252, in execute_callable
    return self.python_callable(*self.op_args, **self.op_kwargs)
           ^^^^^^^^^^^^^^^^^^^^^^^^^^^^^^^^^^^^^^^^^^^^^^^^^^^^^
  File "/opt/airflow/dags/data_ingesting_gcs_dag.py", line 57, in upload_file_to_gcs
    blob.upload_from_filename(local_fpath)
  File "/home/airflow/.local/lib/python3.12/site-packages/google/cloud/storage/blob.py", line 2959, in upload_from_filename
    self._handle_filename_and_upload(
  File "/home/airflow/.local/lib/python3.12/site-packages/google/cloud/storage/blob.py", line 2829, in _handle_filename_and_upload
    self._prep_and_do_upload(
  File "/home/airflow/.local/lib/python3.12/site-packages/google/cloud/storage/blob.py", line 2655, in _prep_and_do_upload
    _raise_from_invalid_response(exc)
  File "/home/airflow/.local/lib/python3.12/site-packages/google/cloud/storage/blob.py", line 4847, in _raise_from_invalid_response
    raise exceptions.from_http_status(response.status_code, message, response=response)
google.api_core.exceptions.NotFound: 404 POST https://storage.googleapis.com/upload/storage/v1/b/ny-rides-joshua-terra-bucket/o?uploadType=multipart: {
  "error": {
    "code": 404,
    "message": "The specified bucket does not exist.",
    "errors": [
      {
        "message": "The specified bucket does not exist.",
        "domain": "global",
        "reason": "notFound"
      }
    ]
  }
}
: ('Request failed with status code', 404, 'Expected one of', <HTTPStatus.OK: 200>)
[2024-05-15T13:07:52.217+0000] {taskinstance.py:1206} INFO - Marking task as UP_FOR_RETRY. dag_id=data_ingestion_gcs_dag, task_id=upload_file_to_gcs_task, run_id=manual__2024-05-15T13:06:01.464781+00:00, execution_date=20240515T130601, start_date=20240515T130751, end_date=20240515T130752
[2024-05-15T13:07:52.232+0000] {standard_task_runner.py:110} ERROR - Failed to execute job 33 for task upload_file_to_gcs_task (404 POST https://storage.googleapis.com/upload/storage/v1/b/ny-rides-joshua-terra-bucket/o?uploadType=multipart: {
  "error": {
    "code": 404,
    "message": "The specified bucket does not exist.",
    "errors": [
      {
        "message": "The specified bucket does not exist.",
        "domain": "global",
        "reason": "notFound"
      }
    ]
  }
}
: ('Request failed with status code', 404, 'Expected one of', <HTTPStatus.OK: 200>); 102)
[2024-05-15T13:07:52.247+0000] {local_task_job_runner.py:240} INFO - Task exited with return code 1
[2024-05-15T13:07:52.266+0000] {taskinstance.py:3498} INFO - 0 downstream tasks scheduled from follow-on schedule check
[2024-05-15T13:07:52.267+0000] {local_task_job_runner.py:222} INFO - ::endgroup::
