[2024-05-15T13:02:43.594+0000] {local_task_job_runner.py:120} INFO - ::group::Pre task execution logs
[2024-05-15T13:02:43.601+0000] {taskinstance.py:2076} INFO - Dependencies all met for dep_context=non-requeueable deps ti=<TaskInstance: data_ingestion_gcs_dag.upload_file_to_gcs_task manual__2024-05-15T13:02:16.788807+00:00 [queued]>
[2024-05-15T13:02:43.604+0000] {taskinstance.py:2076} INFO - Dependencies all met for dep_context=requeueable deps ti=<TaskInstance: data_ingestion_gcs_dag.upload_file_to_gcs_task manual__2024-05-15T13:02:16.788807+00:00 [queued]>
[2024-05-15T13:02:43.605+0000] {taskinstance.py:2306} INFO - Starting attempt 1 of 2
[2024-05-15T13:02:43.610+0000] {taskinstance.py:2330} INFO - Executing <Task(PythonOperator): upload_file_to_gcs_task> on 2024-05-15 13:02:16.788807+00:00
[2024-05-15T13:02:43.613+0000] {warnings.py:110} WARNING - /home/***/.local/lib/python3.12/site-packages/***/task/task_runner/standard_task_runner.py:61: DeprecationWarning: This process (pid=71) is multi-threaded, use of fork() may lead to deadlocks in the child.
  pid = os.fork()

[2024-05-15T13:02:43.614+0000] {standard_task_runner.py:63} INFO - Started process 73 to run task
[2024-05-15T13:02:43.614+0000] {standard_task_runner.py:90} INFO - Running: ['***', 'tasks', 'run', 'data_ingestion_gcs_dag', 'upload_file_to_gcs_task', 'manual__2024-05-15T13:02:16.788807+00:00', '--job-id', '27', '--raw', '--subdir', 'DAGS_FOLDER/data_ingesting_gcs_dag.py', '--cfg-path', '/tmp/tmprihl9zp4']
[2024-05-15T13:02:43.615+0000] {standard_task_runner.py:91} INFO - Job 27: Subtask upload_file_to_gcs_task
[2024-05-15T13:02:43.634+0000] {task_command.py:426} INFO - Running <TaskInstance: data_ingestion_gcs_dag.upload_file_to_gcs_task manual__2024-05-15T13:02:16.788807+00:00 [running]> on host 980cb962d892
[2024-05-15T13:02:43.669+0000] {taskinstance.py:2648} INFO - Exporting env vars: AIRFLOW_CTX_DAG_OWNER='***' AIRFLOW_CTX_DAG_ID='data_ingestion_gcs_dag' AIRFLOW_CTX_TASK_ID='upload_file_to_gcs_task' AIRFLOW_CTX_EXECUTION_DATE='2024-05-15T13:02:16.788807+00:00' AIRFLOW_CTX_TRY_NUMBER='1' AIRFLOW_CTX_DAG_RUN_ID='manual__2024-05-15T13:02:16.788807+00:00'
[2024-05-15T13:02:43.670+0000] {taskinstance.py:430} INFO - ::endgroup::
[2024-05-15T13:02:43.750+0000] {taskinstance.py:441} INFO - ::group::Post task execution logs
[2024-05-15T13:02:43.751+0000] {taskinstance.py:2905} ERROR - Task failed with exception
Traceback (most recent call last):
  File "/home/airflow/.local/lib/python3.12/site-packages/airflow/models/taskinstance.py", line 465, in _execute_task
    result = _execute_callable(context=context, **execute_callable_kwargs)
             ^^^^^^^^^^^^^^^^^^^^^^^^^^^^^^^^^^^^^^^^^^^^^^^^^^^^^^^^^^^^^
  File "/home/airflow/.local/lib/python3.12/site-packages/airflow/models/taskinstance.py", line 432, in _execute_callable
    return execute_callable(context=context, **execute_callable_kwargs)
           ^^^^^^^^^^^^^^^^^^^^^^^^^^^^^^^^^^^^^^^^^^^^^^^^^^^^^^^^^^^^
  File "/home/airflow/.local/lib/python3.12/site-packages/airflow/models/baseoperator.py", line 400, in wrapper
    return func(self, *args, **kwargs)
           ^^^^^^^^^^^^^^^^^^^^^^^^^^^
  File "/home/airflow/.local/lib/python3.12/site-packages/airflow/operators/python.py", line 235, in execute
    return_value = self.execute_callable()
                   ^^^^^^^^^^^^^^^^^^^^^^^
  File "/home/airflow/.local/lib/python3.12/site-packages/airflow/operators/python.py", line 252, in execute_callable
    return self.python_callable(*self.op_args, **self.op_kwargs)
           ^^^^^^^^^^^^^^^^^^^^^^^^^^^^^^^^^^^^^^^^^^^^^^^^^^^^^
  File "/opt/airflow/dags/data_ingesting_gcs_dag.py", line 57, in upload_file_to_gcs
    blob.upload_from_filename(local_fpath)
  File "/home/airflow/.local/lib/python3.12/site-packages/google/cloud/storage/blob.py", line 2959, in upload_from_filename
    self._handle_filename_and_upload(
  File "/home/airflow/.local/lib/python3.12/site-packages/google/cloud/storage/blob.py", line 2829, in _handle_filename_and_upload
    self._prep_and_do_upload(
  File "/home/airflow/.local/lib/python3.12/site-packages/google/cloud/storage/blob.py", line 2637, in _prep_and_do_upload
    created_json = self._do_upload(
                   ^^^^^^^^^^^^^^^^
  File "/home/airflow/.local/lib/python3.12/site-packages/google/cloud/storage/blob.py", line 2443, in _do_upload
    response = self._do_multipart_upload(
               ^^^^^^^^^^^^^^^^^^^^^^^^^^
  File "/home/airflow/.local/lib/python3.12/site-packages/google/cloud/storage/blob.py", line 1914, in _do_multipart_upload
    hostname=hostname, bucket_path=self.bucket.path, api_version=_API_VERSION
                                   ^^^^^^^^^^^^^^^^
  File "/home/airflow/.local/lib/python3.12/site-packages/google/cloud/storage/bucket.py", line 1173, in path
    raise ValueError("Cannot determine path without bucket name.")
ValueError: Cannot determine path without bucket name.
[2024-05-15T13:02:43.756+0000] {taskinstance.py:1206} INFO - Marking task as UP_FOR_RETRY. dag_id=data_ingestion_gcs_dag, task_id=upload_file_to_gcs_task, run_id=manual__2024-05-15T13:02:16.788807+00:00, execution_date=20240515T130216, start_date=20240515T130243, end_date=20240515T130243
[2024-05-15T13:02:43.761+0000] {standard_task_runner.py:110} ERROR - Failed to execute job 27 for task upload_file_to_gcs_task (Cannot determine path without bucket name.; 73)
[2024-05-15T13:02:43.799+0000] {local_task_job_runner.py:240} INFO - Task exited with return code 1
[2024-05-15T13:02:43.809+0000] {taskinstance.py:3498} INFO - 0 downstream tasks scheduled from follow-on schedule check
[2024-05-15T13:02:43.810+0000] {local_task_job_runner.py:222} INFO - ::endgroup::
